<?xml version="1.0" ?>
<!-- =================================================================================== -->
<!-- |    This document was autogenerated by xacro from irb2400_with_simple_track_workspace.xacro | -->
<!-- |    EDITING THIS FILE BY HAND IS NOT RECOMMENDED                                 | -->
<!-- =================================================================================== -->
<robot name="framefab_irb2400_simple_track" xmlns:xacro="http://ros.org/wiki/xacro">
  <!-- Conversion were obtained from http://www.e-paint.co.uk/Lab_values.asp
       unless otherwise stated. -->
  <!--	<xacro:include filename="$(find asw_end_effector)/urdf/asw_eef_macro.xacro"/>-->
  <!--	<xacro:include filename="$(find framefab_irb6600_support)/urdf/simple_linear_track_demo_cell_macro.xacro"/>-->
  <!-- link list -->
  <link name="robot_base_link">
    <visual>
      <origin rpy="0 0 0" xyz="0 0 0"/>
      <geometry>
        <mesh filename="package://abb_irb2400_support/meshes/irb2400/visual/base_link.dae"/>
      </geometry>
      <material name="">
        <color rgba="0.7372549 0.3490196 0.1607843 1"/>
      </material>
    </visual>
    <collision>
      <geometry>
        <mesh filename="package://abb_irb2400_support/meshes/irb2400/collision/base_link.stl"/>
      </geometry>
      <material name="">
        <color rgba="1 1 0 1"/>
      </material>
    </collision>
  </link>
  <link name="robot_link_1">
    <visual>
      <origin rpy="0 0 0" xyz="0 0 0"/>
      <geometry>
        <mesh filename="package://abb_irb2400_support/meshes/irb2400/visual/link_1.dae"/>
      </geometry>
      <material name="">
        <color rgba="0.7372549 0.3490196 0.1607843 1"/>
      </material>
    </visual>
    <collision>
      <origin rpy="0 0 0" xyz="0 0 0"/>
      <geometry>
        <mesh filename="package://abb_irb2400_support/meshes/irb2400/collision/link_1.stl"/>
      </geometry>
      <material name="">
        <color rgba="1 1 0 1"/>
      </material>
    </collision>
  </link>
  <link name="robot_link_2">
    <visual>
      <origin rpy="0 0 0" xyz="0 0 0"/>
      <geometry>
        <mesh filename="package://abb_irb2400_support/meshes/irb2400/visual/link_2.dae"/>
      </geometry>
      <material name="">
        <color rgba="0.7372549 0.3490196 0.1607843 1"/>
      </material>
    </visual>
    <collision>
      <origin rpy="0 0 0" xyz="0 0 0"/>
      <geometry>
        <mesh filename="package://abb_irb2400_support/meshes/irb2400/collision/link_2_whole.stl"/>
      </geometry>
      <material name="">
        <color rgba="1 1 0 1"/>
      </material>
    </collision>
  </link>
  <link name="robot_link_3">
    <visual>
      <origin rpy="0 0 0" xyz="0 0 0"/>
      <geometry>
        <mesh filename="package://abb_irb2400_support/meshes/irb2400/visual/link_3.dae"/>
      </geometry>
      <material name="">
        <color rgba="0.7372549 0.3490196 0.1607843 1"/>
      </material>
    </visual>
    <collision>
      <origin rpy="0 0 0" xyz="0 0 0"/>
      <geometry>
        <mesh filename="package://abb_irb2400_support/meshes/irb2400/collision/link_3.stl"/>
      </geometry>
      <material name="">
        <color rgba="1 1 0 1"/>
      </material>
    </collision>
  </link>
  <link name="robot_link_4">
    <visual>
      <origin rpy="0 0 0" xyz="0 0 0"/>
      <geometry>
        <mesh filename="package://abb_irb2400_support/meshes/irb2400/visual/link_4.dae"/>
      </geometry>
      <material name="">
        <color rgba="0.7372549 0.3490196 0.1607843 1"/>
      </material>
    </visual>
    <collision>
      <origin rpy="0 0 0" xyz="0 0 0"/>
      <geometry>
        <mesh filename="package://abb_irb2400_support/meshes/irb2400/collision/link_4.stl"/>
      </geometry>
      <material name="">
        <color rgba="1 1 0 1"/>
      </material>
    </collision>
  </link>
  <link name="robot_link_5">
    <visual>
      <origin rpy="0 0 0" xyz="0 0 0"/>
      <geometry>
        <mesh filename="package://abb_irb2400_support/meshes/irb2400/visual/link_5.dae"/>
      </geometry>
      <material name="">
        <color rgba="0.7372549 0.3490196 0.1607843 1"/>
      </material>
    </visual>
    <collision>
      <origin rpy="0 0 0" xyz="0 0 0"/>
      <geometry>
        <mesh filename="package://abb_irb2400_support/meshes/irb2400/collision/link_5.stl"/>
      </geometry>
      <material name="">
        <color rgba="1 1 0 1"/>
      </material>
    </collision>
  </link>
  <link name="robot_link_6">
    <visual>
      <origin rpy="0 0 0" xyz="0 0 0"/>
      <geometry>
        <mesh filename="package://abb_irb2400_support/meshes/irb2400/visual/link_6.dae"/>
      </geometry>
      <material name="">
        <color rgba="0.1882353 0.1960784 0.2039216 1"/>
      </material>
    </visual>
    <collision>
      <origin rpy="0 0 0" xyz="0 0 0"/>
      <geometry>
        <mesh filename="package://abb_irb2400_support/meshes/irb2400/collision/link_6.stl"/>
      </geometry>
      <material name="">
        <color rgba="1 1 0 1"/>
      </material>
    </collision>
  </link>
  <link name="robot_tool0"/>
  <!-- end of link list -->
  <!-- joint list -->
  <joint name="robot_joint_1" type="revolute">
    <origin rpy="0 0 0" xyz="0 0 0"/>
    <parent link="robot_base_link"/>
    <child link="robot_link_1"/>
    <axis xyz="0 0 1"/>
    <limit effort="0" lower="-3.1416" upper="3.1416" velocity="2.618"/>
  </joint>
  <joint name="robot_joint_2" type="revolute">
    <origin rpy="0 0 0" xyz="0.1 0 0.615"/>
    <parent link="robot_link_1"/>
    <child link="robot_link_2"/>
    <axis xyz="0 1 0"/>
    <limit effort="0" lower="-1.7453" upper="1.9199" velocity="2.618"/>
  </joint>
  <joint name="robot_joint_3" type="revolute">
    <origin rpy="0 0 0" xyz="0 0 0.705"/>
    <parent link="robot_link_2"/>
    <child link="robot_link_3"/>
    <axis xyz="0 1 0"/>
    <limit effort="0" lower="-1.0472" upper="1.1345" velocity="2.618"/>
  </joint>
  <joint name="robot_joint_4" type="revolute">
    <origin rpy="0 0 0" xyz="0.258 0 0.135"/>
    <parent link="robot_link_3"/>
    <child link="robot_link_4"/>
    <axis xyz="1 0 0"/>
    <limit effort="0" lower="-3.49" upper="3.49" velocity="6.2832"/>
  </joint>
  <joint name="robot_joint_5" type="revolute">
    <origin rpy="0 0 0" xyz="0.497 0 0"/>
    <parent link="robot_link_4"/>
    <child link="robot_link_5"/>
    <axis xyz="0 1 0"/>
    <limit effort="0" lower="-2.0944" upper="2.0944" velocity="6.2832"/>
  </joint>
  <joint name="robot_joint_6" type="revolute">
    <origin rpy="0 0 0" xyz="0.085 0 0"/>
    <parent link="robot_link_5"/>
    <child link="robot_link_6"/>
    <axis xyz="1 0 0"/>
    <limit effort="0" lower="-6.9813" upper="6.9813" velocity="7.854"/>
  </joint>
  <joint name="robot_joint_6-tool0" type="fixed">
    <parent link="robot_link_6"/>
    <child link="robot_tool0"/>
    <origin rpy="0 1.57079632679 0" xyz="0 0 0"/>
  </joint>
  <!-- end of joint list -->
  <!-- ROS base_link to ABB World Coordinates transform -->
  <link name="robot_base"/>
  <joint name="robot_base_link-base" type="fixed">
    <origin rpy="0 0 0" xyz="0 0 0"/>
    <parent link="robot_base_link"/>
    <child link="robot_base"/>
  </joint>
  <!--	Link list-->
  <link name="linear_axis_base_link">
    <visual>
      <origin xyz="0 0 0"/>
      <geometry>
        <box size="4 0.1 0.1"/>
      </geometry>
      <material name="yellow">
        <color rgba="1.0 1.0 0 1.0"/>
      </material>
    </visual>
    <collision>
      <origin xyz="0 0 0"/>
      <geometry>
        <box size="4 0.1 0.1"/>
      </geometry>
      <material name="yellow">
        <color rgba="1.0 1.0 0 1.0"/>
      </material>
    </collision>
  </link>
  <!--	<link name="${prefix}robot_mount"/>-->
  <!--	End of link list-->
  <!-- Joint list -->
  <!--  <joint name="${prefix}actuation_joint" type="prismatic">-->
  <!--    <parent link="${prefix}base_link" />-->
  <!--    <child link="${prefix}robot_mount" />-->
  <!--    <origin xyz="0 0 ${0.5*rail_cross_section}"/>-->
  <!--    <axis xyz="1 0 0"/>-->
  <!--    <limit lower="-2" upper="2" effort="1" velocity="0.1"/>-->
  <!--  </joint>-->
  <!-- End of joint list -->
  <!--  <xacro:simple_linear_track_demo_cell prefix=""/>-->
  <!-- Link list -->
  <link name="base_link"/>
  <!-- End of link list -->
  <!-- Joint list -->
  <!--	<joint name="robot_to_base_link" type="fixed">-->
  <!--    <origin xyz="0 0 0" rpy="0 0 ${half_pi}"/>-->
  <!--    <parent link="base_link"/>-->
  <!--    <child link="robot_base_link"/>-->
  <!--  </joint>-->
  <!--	bind the rail to word_frame, can be disabled if using modile platform-->
  <joint name="linear_axis_to_base_link" type="fixed">
    <origin rpy="0 0 0" xyz="0 0 0"/>
    <parent link="base_link"/>
    <child link="linear_axis_base_link"/>
  </joint>
  <!--  <joint name="robot_to_linear_axis" type="fixed">-->
  <!--    <origin xyz="0 0 0" rpy="0 0 -${half_pi}"/>-->
  <!--    <parent link="linear_axis_robot_mount"/>-->
  <!--    <child link="robot_base_link"/>-->
  <!--  </joint>-->
  <joint name="actuation_joint" type="prismatic">
    <parent link="linear_axis_base_link"/>
    <child link="robot_base_link"/>
    <origin xyz="0 0 0.05"/>
    <axis xyz="1 0 0"/>
    <limit effort="1" lower="-2" upper="2" velocity="0.1"/>
  </joint>
  <!--	<joint name="ee_to_robot" type="fixed">-->
  <!--		<parent link="robot_tool0"/>-->
  <!--		<child link="eef_base_link"/>-->
  <!--		<origin xyz="0 0 0" rpy="0 0 0"/>-->
  <!--	</joint>-->
  <!-- End of joint list -->
</robot>
