<?xml version="1.0" ?>
<!-- =================================================================================== -->
<!-- |    This document was autogenerated by xacro from choreo_kr5_arc_linear_track_workspace.xacro | -->
<!-- |    EDITING THIS FILE BY HAND IS NOT RECOMMENDED                                 | -->
<!-- =================================================================================== -->
<robot name="choreo_kr5_arc_workspace" xmlns:xacro="http://ros.org/wiki/xacro">
  <!-- LINKS -->
  <!-- base link -->
  <link name="robot_base_link">
    <inertial>
      <origin rpy="0 0 0" xyz="-0.017519394031846 8.11394768450848E-07 0.0975924044854325"/>
      <mass value="7.58585707666653"/>
      <inertia ixx="0.0441803207364147" ixy="5.37433593375545E-07" ixz="0.004045564920652" iyy="0.0584309411563095" iyz="-4.8990117845347E-07" izz="0.0514875586171667"/>
    </inertial>
    <visual>
      <origin rpy="0 0 0" xyz="0 0 0"/>
      <geometry>
        <mesh filename="package://kuka_kr5_support/meshes/kr5_arc/visual/base_link.dae"/>
      </geometry>
    </visual>
    <collision>
      <origin rpy="0 0 0" xyz="0 0 0"/>
      <geometry>
        <mesh filename="package://kuka_kr5_support/meshes/kr5_arc/collision/base_link.stl"/>
      </geometry>
    </collision>
  </link>
  <!-- link 1 (A1) -->
  <link name="robot_link_1">
    <inertial>
      <origin rpy="0 0 0" xyz="0.0359968408135882 0.00783796591813503 -0.0864969937502713"/>
      <mass value="5.77242340173648"/>
      <inertia ixx="0.0327019582662897" ixy="-0.00189987845379704" ixz="0.00937014136132958" iyy="0.0373787564144547" iyz="-0.00197023031658988" izz="0.0348614383349291"/>
    </inertial>
    <visual>
      <origin rpy="0 0 0" xyz="0 0 0"/>
      <geometry>
        <mesh filename="package://kuka_kr5_support/meshes/kr5_arc/visual/link_1.dae"/>
      </geometry>
    </visual>
    <collision>
      <origin rpy="0 0 0" xyz="0 0 0"/>
      <geometry>
        <mesh filename="package://kuka_kr5_support/meshes/kr5_arc/collision/link_1.stl"/>
      </geometry>
    </collision>
  </link>
  <!-- link 2 -->
  <link name="robot_link_2">
    <inertial>
      <origin rpy="0 0 0" xyz="0.00610231661046294 0.0401115026555897 -0.11531122862673"/>
      <mass value="4.64974639735464"/>
      <inertia ixx="0.0663459530931455" ixy="0.000173652478770081" ixz="0.000586191290902105" iyy="0.070407913174161" iyz="-0.00203071071007864" izz="0.0102816377550493"/>
    </inertial>
    <visual>
      <origin rpy="0 0 0" xyz="0 0 0"/>
      <geometry>
        <mesh filename="package://kuka_kr5_support/meshes/kr5_arc/visual/link_2.dae"/>
      </geometry>
    </visual>
    <collision>
      <origin rpy="0 0 0" xyz="0 0 0"/>
      <geometry>
        <mesh filename="package://kuka_kr5_support/meshes/kr5_arc/collision/link_2.stl"/>
      </geometry>
    </collision>
  </link>
  <!-- link 3 -->
  <link name="robot_link_3">
    <inertial>
      <origin rpy="0 0 0" xyz="0.0755031858462784 -0.046481517407519 -0.00506472105904233"/>
      <mass value="4.3593398708568"/>
      <inertia ixx="0.0202008069207718" ixy="5.72394748332304E-05" ixz="0.000556621203065716" iyy="0.0246796752429931" iyz="0.000697020296811431" izz="0.0178067561136726"/>
    </inertial>
    <visual>
      <origin rpy="0 0 0" xyz="0 0 0"/>
      <geometry>
        <mesh filename="package://kuka_kr5_support/meshes/kr5_arc/visual/link_3.dae"/>
      </geometry>
    </visual>
    <collision>
      <origin rpy="0 0 0" xyz="0 0 0"/>
      <geometry>
        <mesh filename="package://kuka_kr5_support/meshes/kr5_arc/collision/link_3.stl"/>
      </geometry>
    </collision>
  </link>
  <!-- link 4 -->
  <link name="robot_link_4">
    <inertial>
      <origin rpy="0 0 0" xyz="0.0857493724873204 -0.00149370513017266 -0.00271609825446984"/>
      <mass value="2.06809715541017"/>
      <inertia ixx="0.00444943757623485" ixy="-0.000424915429214687" ixz="-0.000117340671961173" iyy="0.00882693069799353" iyz="0.000136971152627904" izz="0.0101131228921778"/>
    </inertial>
    <visual>
      <origin rpy="0 0 0" xyz="0 0 0"/>
      <geometry>
        <mesh filename="package://kuka_kr5_support/meshes/kr5_arc/visual/link_4.dae"/>
      </geometry>
    </visual>
    <collision>
      <origin rpy="0 0 0" xyz="0 0 0"/>
      <geometry>
        <mesh filename="package://kuka_kr5_support/meshes/kr5_arc/collision/link_4.stl"/>
      </geometry>
    </collision>
  </link>
  <!-- link 5 -->
  <link name="robot_link_5">
    <inertial>
      <origin rpy="0 0 0" xyz="0 0 0"/>
      <mass value="0.328309098974388"/>
      <inertia ixx="0.000221789219477276" ixy="-9.59628913869705E-07" ixz="1.40395663663479E-20" iyy="0.000321152451627032" iyz="-4.44973606670705E-20" izz="0.000275966419870925"/>
    </inertial>
    <visual>
      <origin rpy="0 0 0" xyz="0 0 0"/>
      <geometry>
        <mesh filename="package://kuka_kr5_support/meshes/kr5_arc/visual/link_5.dae"/>
      </geometry>
    </visual>
    <collision>
      <origin rpy="0 0 0" xyz="0 0 0"/>
      <geometry>
        <mesh filename="package://kuka_kr5_support/meshes/kr5_arc/collision/link_5.stl"/>
      </geometry>
    </collision>
  </link>
  <!-- link 6 -->
  <link name="robot_link_6">
    <inertial>
      <origin rpy="0 0 0" xyz="0.00983949894991115 -2.78372724487979E-05 -1.11022302462516E-15"/>
      <mass value="0.0789494717998531"/>
      <inertia ixx="3.53285039019399E-05" ixy="-3.23299732456798E-08" ixz="-6.9643163510009E-19" iyy="2.30177957763861E-05" iyz="-9.26550270485857E-19" izz="2.28539400944714E-05"/>
    </inertial>
    <visual>
      <origin rpy="0 0 0" xyz="0 0 0"/>
      <geometry>
        <mesh filename="package://kuka_kr5_support/meshes/kr5_arc/visual/link_6.dae"/>
      </geometry>
    </visual>
    <collision>
      <origin rpy="0 0 0" xyz="0 0 0"/>
      <geometry>
        <mesh filename="package://kuka_kr5_support/meshes/kr5_arc/collision/link_6.stl"/>
      </geometry>
    </collision>
  </link>
  <!-- tool link -->
  <!-- This frame corresponds to the $FLANGE coordinate system in KUKA KRC controllers. -->
  <link name="robot_tool0"/>
  <!-- END LINKS -->
  <!-- JOINTS -->
  <!-- joint 1 (A1) -->
  <joint name="robot_joint_a1" type="revolute">
    <origin rpy="3.14159265359 0 0" xyz="0 0 0.4"/>
    <parent link="robot_base_link"/>
    <child link="robot_link_1"/>
    <axis xyz="0 0 1"/>
    <limit effort="0" lower="-2.70526034059" upper="2.70526034059" velocity="2.68780704807"/>
  </joint>
  <!-- joint 2 (A2) -->
  <joint name="robot_joint_a2" type="revolute">
    <origin rpy="1.57079632679 0 0" xyz="0.18 0 0"/>
    <parent link="robot_link_1"/>
    <child link="robot_link_2"/>
    <axis xyz="0 0 1"/>
    <limit effort="0" lower="-3.14159265359" upper="1.1344640138" velocity="2.68780704807"/>
  </joint>
  <!-- joint 3 (A3) -->
  <joint name="robot_joint_a3" type="revolute">
    <origin rpy="0 0 0" xyz="0.6 0 0"/>
    <parent link="robot_link_2"/>
    <child link="robot_link_3"/>
    <axis xyz="0 0 1"/>
    <limit effort="0" lower="-0.261799387799" upper="2.75762021815" velocity="3.97935069455"/>
  </joint>
  <!-- joint 4 (A4) -->
  <joint name="robot_joint_a4" type="revolute">
    <origin rpy="0 -1.57079632679 0" xyz="0 -0.12 0"/>
    <parent link="robot_link_3"/>
    <child link="robot_link_4"/>
    <axis xyz="0 0 1"/>
    <limit effort="0" lower="-6.10865238198" upper="6.10865238198" velocity="5.98647933434"/>
  </joint>
  <!-- joint 5 (A5) -->
  <joint name="robot_joint_a5" type="revolute">
    <origin rpy="0 1.57079632679 0" xyz="0 0 -0.62"/>
    <parent link="robot_link_4"/>
    <child link="robot_link_5"/>
    <axis xyz="0 0 1"/>
    <limit effort="0" lower="-2.26892802759" upper="2.26892802759" velocity="6.70206432766"/>
  </joint>
  <!-- joint 6 (A6) -->
  <joint name="robot_joint_a6" type="revolute">
    <origin rpy="0 -1.57079632679 0" xyz="0 0 0"/>
    <parent link="robot_link_5"/>
    <child link="robot_link_6"/>
    <axis xyz="0 0 1"/>
    <limit effort="0" lower="-6.10865238198" upper="6.10865238198" velocity="12.5838239069"/>
  </joint>
  <!-- tool frame - fixed frame -->
  <joint name="robot_joint_a6-tool0" type="fixed">
    <parent link="robot_link_6"/>
    <child link="robot_tool0"/>
    <origin rpy="0 -3.14159265359 -1.57079632679" xyz="0 0 -0.115"/>
  </joint>
  <!-- END JOINTS -->
  <!-- ROS base_link to KUKA $ROBROOT coordinate system transform -->
  <link name="robot_base"/>
  <joint name="robot_base_link-base" type="fixed">
    <origin rpy="0 0 0" xyz="0 0 0"/>
    <parent link="robot_base_link"/>
    <child link="robot_base"/>
  </joint>
  <!-- link list -->
  <link name="eef_base_link">
    <visual>
      <origin rpy="0 0 0" xyz="8.8e-05 0.000769 -0.002121"/>
      <geometry>
        <mesh filename="package://asw_end_effector/meshes/visual/asw_hotend_end_effector.stl" scale=".001 .001 .001"/>
      </geometry>
      <material name="grey">
        <color rgba="0.5 0.5 0.5 1.0"/>
      </material>
    </visual>
    <collision>
      <origin rpy="0 0 0" xyz="8.8e-05 0.000769 -0.002121"/>
      <geometry>
        <mesh filename="package://asw_end_effector/meshes/collision/asw_hotend_end_effector_shrinked_tip-6mm.stl" scale=".001 .001 .001"/>
      </geometry>
      <material name="red">
        <color rgba="1 0 0 1"/>
      </material>
    </collision>
  </link>
  <link name="eef_tcp_frame"/>
  <!-- end of link list -->
  <!-- joint list -->
  <joint name="eef_base_to_tcp" type="fixed">
    <origin rpy="0.0 1.57079632679 0.0" xyz="0.150539 0.001052 0.119157"/>
    <parent link="eef_base_link"/>
    <child link="eef_tcp_frame"/>
  </joint>
  <!-- end of joint list -->
  <!--	Link list-->
  <link name="linear_axis_base_link">
    <visual>
      <geometry>
        <mesh filename="package://ucla_linear_axis/meshes/visual/ucla_linear_axis_visual_rail.stl" scale=".001 .001 .001"/>
      </geometry>
      <material name="">
        <color rgba="0.772549019608 0.780392156863 0.76862745098 1.0"/>
      </material>
    </visual>
    <collision>
      <geometry>
        <mesh filename="package://ucla_linear_axis/meshes/collision/ucla_linear_axis_collision_rail.stl" scale=".001 .001 .001"/>
      </geometry>
      <material name="">
        <color rgba="0.772549019608 0.780392156863 0.76862745098 1.0"/>
      </material>
    </collision>
  </link>
  <link name="linear_axis_zero"/>
  <link name="linear_axis_carriage">
    <visual>
      <geometry>
        <mesh filename="package://ucla_linear_axis/meshes/visual/ucla_linear_axis_visual_carriage.stl" scale=".001 .001 .001"/>
      </geometry>
      <material name="">
        <color rgba="0.15 0.415 0.165 1.0"/>
      </material>
    </visual>
    <collision>
      <geometry>
        <mesh filename="package://ucla_linear_axis/meshes/collision/ucla_linear_axis_collision_carriage.stl" scale=".001 .001 .001"/>
      </geometry>
      <material name="">
        <color rgba="0.15 0.415 0.165 1.0"/>
      </material>
    </collision>
  </link>
  <link name="linear_axis_robot_mount"/>
  <!--	End of link list-->
  <!-- Joint list -->
  <joint name="linear_axis_joint_1" type="fixed">
    <parent link="linear_axis_base_link"/>
    <child link="linear_axis_zero"/>
    <origin rpy="0 0 0" xyz="-3.153 -0.212 0.470"/>
  </joint>
  <joint name="linear_axis_actuation_joint" type="prismatic">
    <parent link="linear_axis_zero"/>
    <child link="linear_axis_carriage"/>
    <origin rpy="0 0 0" xyz="0 0 0"/>
    <axis xyz="1 0 0"/>
    <limit effort="1" lower="0" upper="5.4" velocity="1"/>
  </joint>
  <joint name="linear_axis_joint_3" type="fixed">
    <parent link="linear_axis_carriage"/>
    <child link="linear_axis_robot_mount"/>
    <origin rpy="0 0 0" xyz="0 0 0.470"/>
  </joint>
  <!-- End of joint list -->
  <!-- Link list -->
  <link name="base_link"/>
  <!-- End of link list -->
  <material name="workcell_material">
    <color rgba="0.8 1.0 0.8 0.2"/>
  </material>
  <link name="print_bed">
    <visual>
      <origin xyz="2.1 0 0.395"/>
      <geometry>
        <box size="1.0 3.0 0.01"/>
      </geometry>
      <material name="workcell_material"/>
    </visual>
  </link>
  <joint name="world_to_print_bed" type="fixed">
    <parent link="base_link"/>
    <child link="print_bed"/>
    <origin xyz="0 0 0"/>
  </joint>
  <!-- Joint list -->
  <!--bind the rail to word_frame, can be disabled if using modile platform-->
  <joint name="linear_axis_to_base_link" type="fixed">
    <origin rpy="0 0 1.57079632679" xyz="0 0 0"/>
    <parent link="base_link"/>
    <child link="linear_axis_base_link"/>
  </joint>
  <joint name="robot_to_linear_axis" type="fixed">
    <origin rpy="0 0 -1.57079632679" xyz="0 0 0"/>
    <parent link="linear_axis_robot_mount"/>
    <child link="robot_base_link"/>
  </joint>
  <joint name="ee_to_robot" type="fixed">
    <parent link="robot_tool0"/>
    <child link="eef_base_link"/>
    <origin rpy="0 0 0" xyz="0 0 0"/>
  </joint>
  <!-- End of joint list -->
</robot>
