<?xml version="1.0" ?>
<robot xmlns:xacro="http://ros.org/wiki/xacro">
	<xacro:property name="half_pi" value="1.5707963267948966"/>
	<xacro:include filename="$(find ucla_linear_axis)/urdf/resources/materials.xacro"/>

	<xacro:macro name="ucla_linear_axis" params="prefix">

	<!--	Link list-->

	<link name="${prefix}base_link">
	  <visual>
		<geometry>
		  <mesh filename="package://ucla_linear_axis/meshes/visual/ucla_linear_axis_visual_rail.stl" scale=".001 .001 .001"/>
		</geometry>
		<xacro:material_gudel_gray/>
	  </visual>
	  <collision>
		<geometry>
		  <mesh filename="package://ucla_linear_axis/meshes/collision/ucla_linear_axis_collision_rail.stl" scale=".001 .001 .001"/>
		</geometry>
		<xacro:material_gudel_gray/>
	  </collision>
	</link>

	<link name="${prefix}zero"/>

  <link name="${prefix}carriage">
    <visual>
      <geometry>
        <mesh filename="package://ucla_linear_axis/meshes/visual/ucla_linear_axis_visual_carriage.stl" scale=".001 .001 .001"/>
      </geometry>
			<xacro:material_gudel_green/>
    </visual>
    <collision>
      <geometry>
        <mesh filename="package://ucla_linear_axis/meshes/collision/ucla_linear_axis_collision_carriage.stl" scale=".001 .001 .001"/>
      </geometry>
			<xacro:material_gudel_green/>
    </collision>
  </link>

	<link name="${prefix}robot_mount"/>

	<!--	End of link list-->

	<!-- Joint list -->
  <joint name="${prefix}joint_1" type="fixed">
    <parent link="${prefix}base_link"/>
    <child link="${prefix}zero"/>
    <origin xyz="-3.153 -0.212 0.470" rpy="0 0 0"/>
  </joint>

  <joint name="${prefix}actuation_joint" type="prismatic">
    <parent link="${prefix}zero"/>
    <child link="${prefix}carriage"/>
    <origin xyz="0 0 0" rpy="0 0 0"/>
    <axis xyz="1 0 0"/>
    <limit lower="0" upper="5.4" effort="1" velocity="1"/>
  </joint>

	<joint name="${prefix}joint_3" type="fixed">
    <parent link="${prefix}carriage"/>
    <child link="${prefix}robot_mount"/>
    <origin xyz="0 0 0.470" rpy="0 0 0"/>
  </joint>
	<!-- End of joint list -->

	</xacro:macro>
</robot>
