<?xml version="1.0" ?>
<!-- =================================================================================== -->
<!-- |    This document was autogenerated by xacro from eth_rfl.xacro                  | -->
<!-- |    EDITING THIS FILE BY HAND IS NOT RECOMMENDED                                 | -->
<!-- =================================================================================== -->
<robot name="eth_rfl" xmlns:xacro="http://ros.org/wiki/xacro">
  <!-- link list -->
  <link name="robot_base_link">
    <collision name="collision">
      <geometry>
        <mesh filename="package://abb_irb6600_support/meshes/irb6640/collision/base_link.stl"/>
      </geometry>
      <material name="yellow">
        <color rgba="0 1 1 1"/>
      </material>
    </collision>
    <visual name="visual">
      <geometry>
        <mesh filename="package://abb_irb6600_support/meshes/irb6640/visual/base_link.stl"/>
      </geometry>
      <material name="orange">
        <color rgba="1 0.43 0 1"/>
      </material>
    </visual>
  </link>
  <link name="robot_link_1">
    <collision name="collision">
      <geometry>
        <mesh filename="package://abb_irb6600_support/meshes/irb6640/collision/link_1.stl"/>
      </geometry>
      <material name="yellow"/>
    </collision>
    <visual name="visual">
      <geometry>
        <mesh filename="package://abb_irb6600_support/meshes/irb6640/visual/link_1.stl"/>
      </geometry>
      <material name="orange"/>
    </visual>
  </link>
  <link name="robot_link_2">
    <collision name="collision">
      <geometry>
        <mesh filename="package://abb_irb6600_support/meshes/irb6640/collision/link_2.stl"/>
      </geometry>
      <material name="yellow"/>
    </collision>
    <visual name="visual">
      <geometry>
        <mesh filename="package://abb_irb6600_support/meshes/irb6640/visual/link_2.stl"/>
      </geometry>
      <material name="orange"/>
    </visual>
  </link>
  <link name="robot_link_3">
    <collision name="collision">
      <geometry>
        <mesh filename="package://abb_irb6600_support/meshes/irb6640/collision/link_3.stl"/>
      </geometry>
      <material name="yellow"/>
    </collision>
    <visual name="visual">
      <geometry>
        <mesh filename="package://abb_irb6600_support/meshes/irb6640/visual/link_3.stl"/>
      </geometry>
      <material name="orange"/>
    </visual>
  </link>
  <link name="robot_link_4">
    <collision name="collision">
      <geometry>
        <mesh filename="package://abb_irb6600_support/meshes/irb6640/collision/link_4.stl"/>
      </geometry>
      <material name="yellow"/>
    </collision>
    <visual name="visual">
      <geometry>
        <mesh filename="package://abb_irb6600_support/meshes/irb6640/visual/link_4.stl"/>
      </geometry>
      <material name="orange"/>
    </visual>
  </link>
  <link name="robot_link_5">
    <collision name="collision">
      <geometry>
        <mesh filename="package://abb_irb6600_support/meshes/irb6640/collision/link_5.stl"/>
      </geometry>
      <material name="yellow"/>
    </collision>
    <visual name="visual">
      <geometry>
        <mesh filename="package://abb_irb6600_support/meshes/irb6640/visual/link_5.stl"/>
      </geometry>
      <material name="orange"/>
    </visual>
  </link>
  <link name="robot_link_6">
    <collision name="collision">
      <geometry>
        <mesh filename="package://abb_irb6600_support/meshes/irb6640/collision/link_6.stl"/>
      </geometry>
      <material name="yellow"/>
    </collision>
    <visual name="visual">
      <geometry>
        <mesh filename="package://abb_irb6600_support/meshes/irb6640/visual/link_6.stl"/>
      </geometry>
      <material name="orange"/>
    </visual>
  </link>
  <link name="robot_tool0"/>
  <!--Cylinder and piston -->
  <link name="robot_link_cylinder">
    <collision name="collision">
      <geometry>
        <mesh filename="package://abb_irb6600_support/meshes/irb6640/collision/cylinder.stl"/>
      </geometry>
      <material name="yellow"/>
    </collision>
    <visual name="visual">
      <geometry>
        <mesh filename="package://abb_irb6600_support/meshes/irb6640/visual/cylinder.stl"/>
      </geometry>
      <material name="orange"/>
    </visual>
  </link>
  <link name="robot_link_piston">
    <collision name="collision">
      <geometry>
        <mesh filename="package://abb_irb6600_support/meshes/irb6640/collision/piston.stl"/>
      </geometry>
      <material name="yellow"/>
    </collision>
    <visual name="visual">
      <geometry>
        <mesh filename="package://abb_irb6600_support/meshes/irb6640/visual/piston.stl"/>
      </geometry>
      <material name="orange"/>
    </visual>
  </link>
  <!-- end of link list -->
  <!-- joint list -->
  <joint name="robot_joint_1" type="revolute">
    <origin rpy="0 0 0" xyz="0 0 0.227"/>
    <axis xyz="0 0 1"/>
    <parent link="robot_base_link"/>
    <child link="robot_link_1"/>
    <limit effort="0" lower="-2.967" upper="2.967" velocity="1.7453"/>
  </joint>
  <joint name="robot_joint_2" type="revolute">
    <origin rpy="0 0 0" xyz="0.322 0.03 0.551"/>
    <axis xyz="0 1 0"/>
    <parent link="robot_link_1"/>
    <child link="robot_link_2"/>
    <limit effort="0" lower="-1.134" upper="1.4855" velocity="1.5707"/>
  </joint>
  <joint name="robot_joint_3" type="revolute">
    <origin rpy="0 0 0" xyz="0 -0.2 1.07"/>
    <axis xyz="0 1 0"/>
    <parent link="robot_link_2"/>
    <child link="robot_link_3"/>
    <limit effort="0" lower="-3.142" upper="1.222" velocity="1.5707"/>
  </joint>
  <joint name="robot_joint_4" type="revolute">
    <origin rpy="0 0 0" xyz="-0.275 0.181 0.2"/>
    <axis xyz="1 0 0"/>
    <parent link="robot_link_3"/>
    <child link="robot_link_4"/>
    <limit effort="0" lower="-5.236" upper="5.236" velocity="2.9671"/>
  </joint>
  <joint name="robot_joint_5" type="revolute">
    <origin rpy="0 0 0" xyz="1.67 0 0 "/>
    <axis xyz="0 1 0"/>
    <parent link="robot_link_4"/>
    <child link="robot_link_5"/>
    <limit effort="0" lower="-2.094" upper="2.094" velocity="2.4435"/>
  </joint>
  <joint name="robot_joint_6" type="revolute">
    <origin rpy="0 0 0" xyz="0.153 0 0 "/>
    <axis xyz="1 0 0"/>
    <parent link="robot_link_5"/>
    <child link="robot_link_6"/>
    <limit effort="0" lower="-6.283" upper="6.283" velocity="3.3161"/>
  </joint>
  <joint name="robot_joint_6-tool0" type="fixed">
    <parent link="robot_link_6"/>
    <child link="robot_tool0"/>
    <origin rpy="0 1.57079632679 0" xyz=".055 0 0"/>
  </joint>
  <joint name="robot_joint_cylinder" type="fixed">
    <origin rpy="0 -0.170 0" xyz="-0.365 -0.1895 0.405"/>
    <axis xyz="0 1 0"/>
    <parent link="robot_link_1"/>
    <child link="robot_link_cylinder"/>
    <limit effort="0" lower="-2.96705973" upper="2.96705973" velocity="0"/>
  </joint>
  <joint name="robot_joint_piston" type="fixed">
    <origin rpy="0 0 0" xyz="0.475 0 0"/>
    <axis xyz="1 0 0"/>
    <parent link="robot_link_cylinder"/>
    <child link="robot_link_piston"/>
    <limit effort="0" lower="0" upper="0.6" velocity="0"/>
  </joint>
  <!-- end of joint list -->
  <!-- ROS base_link to ABB World Coordinates transform -->
  <link name="robot_base"/>
  <joint name="robot_base_link-base" type="fixed">
    <origin rpy="0 0 0" xyz="0 0 0"/>
    <parent link="robot_base_link"/>
    <child link="robot_base"/>
  </joint>
  <!-- link list -->
  <link name="eef_base_link">
    <visual>
      <origin rpy="0 0 0" xyz="8.8e-05 0.000769 -0.002121"/>
      <geometry>
        <mesh filename="package://mit_arch_suction_gripper/meshes/visual/suction-gripper_mit-arch_visual.stl" scale=".001 .001 .001"/>
      </geometry>
      <material name="grey">
        <color rgba="0.5 0.5 0.5 1.0"/>
      </material>
    </visual>
    <collision>
      <origin rpy="0 0 0" xyz="8.8e-05 0.000769 -0.002121"/>
      <geometry>
        <mesh filename="package://mit_arch_suction_gripper/meshes/collision/suction-gripper_mit-arch_collision.stl" scale=".001 .001 .001"/>
      </geometry>
      <material name="red">
        <color rgba="1 0 0 1"/>
      </material>
    </collision>
  </link>
  <link name="eef_tcp_frame"/>
  <!-- end of link list -->
  <!-- joint list -->
  <joint name="eef_base_to_tcp" type="fixed">
    <origin rpy="0.0 1.57079632679 0.0" xyz="0.145336 0.001949 0.096286"/>
    <parent link="eef_base_link"/>
    <child link="eef_tcp_frame"/>
  </joint>
  <!-- end of joint list -->
  <!--	Link list-->
  <link name="gantry_base_link">
    <visual>
      <geometry>
        <mesh filename="package://eth_rfl_track/meshes/visual/eth_gudel_track_x_rail_visual.stl" scale=".001 .001 .001"/>
      </geometry>
      <material name="">
        <color rgba="0.772549019608 0.780392156863 0.76862745098 1.0"/>
      </material>
    </visual>
    <collision>
      <geometry>
        <mesh filename="package://eth_rfl_track/meshes/collision/eth_gudel_track_x_rail_collision.stl" scale=".001 .001 .001"/>
      </geometry>
      <material name="">
        <color rgba="0.772549019608 0.780392156863 0.76862745098 1.0"/>
      </material>
    </collision>
  </link>
  <link name="gantry_y_bridge">
    <visual>
      <geometry>
        <mesh filename="package://eth_rfl_track/meshes/visual/eth_gudel_track_y_bridge_visual.stl" scale=".001 .001 .001"/>
      </geometry>
      <material name="">
        <color rgba="0.15 0.415 0.165 1.0"/>
      </material>
    </visual>
    <collision>
      <geometry>
        <mesh filename="package://eth_rfl_track/meshes/collision/eth_gudel_track_y_bridge_collision.stl" scale=".001 .001 .001"/>
      </geometry>
      <material name="">
        <color rgba="0.15 0.415 0.165 1.0"/>
      </material>
    </collision>
  </link>
  <link name="gantry_xy_carriage">
    <visual>
      <geometry>
        <mesh filename="package://eth_rfl_track/meshes/visual/eth_gudel_track_xy_carriage_visual.stl" scale=".001 .001 .001"/>
      </geometry>
      <material name="">
        <color rgba="0.15 0.415 0.165 1.0"/>
      </material>
    </visual>
    <collision>
      <geometry>
        <mesh filename="package://eth_rfl_track/meshes/collision/eth_gudel_track_xy_carriage_collision.stl" scale=".001 .001 .001"/>
      </geometry>
      <material name="">
        <color rgba="0.15 0.415 0.165 1.0"/>
      </material>
    </collision>
  </link>
  <link name="gantry_z_carriage">
    <visual>
      <geometry>
        <mesh filename="package://eth_rfl_track/meshes/visual/eth_gudel_track_z_carriage_visual.stl" scale=".001 .001 .001"/>
      </geometry>
      <material name="">
        <color rgba="0.772549019608 0.780392156863 0.76862745098 1.0"/>
      </material>
    </visual>
    <collision>
      <geometry>
        <mesh filename="package://eth_rfl_track/meshes/collision/eth_gudel_track_z_carriage_collision.stl" scale=".001 .001 .001"/>
      </geometry>
      <material name="">
        <color rgba="0.772549019608 0.780392156863 0.76862745098 1.0"/>
      </material>
    </collision>
  </link>
  <link name="gantry_robot_mount"/>
  <!--	End of link list-->
  <!-- Joint list -->
  <joint name="gantry_x_joint" type="prismatic">
    <parent link="gantry_base_link"/>
    <child link="gantry_y_bridge"/>
    <origin rpy="0 0 0" xyz="0 0 0"/>
    <axis xyz="1 0 0"/>
    <limit effort="1" lower="0" upper="20" velocity="1.5"/>
  </joint>
  <joint name="gantry_y_joint" type="prismatic">
    <parent link="gantry_y_bridge"/>
    <child link="gantry_xy_carriage"/>
    <origin rpy="0 0 0" xyz="0 0 0"/>
    <axis xyz="0 1 0"/>
    <limit effort="1" lower="0" upper="12.673" velocity="1.5"/>
  </joint>
  <joint name="gantry_z_joint" type="prismatic">
    <parent link="gantry_xy_carriage"/>
    <child link="gantry_z_carriage"/>
    <origin rpy="0 0 0" xyz="0 0 0"/>
    <axis xyz="0 0 -1"/>
    <limit effort="1" lower="0" upper="1.227" velocity="1"/>
  </joint>
  <joint name="gantry_z_carriage_mount" type="fixed">
    <parent link="gantry_z_carriage"/>
    <child link="gantry_robot_mount"/>
    <origin rpy="0 3.14159265359 0" xyz="0.545 -0.0075 -2.526"/>
  </joint>
  <!-- End of joint list -->
  <!--  <xacro:simple_linear_track_demo_cell prefix=""/>-->
  <!-- Link list -->
  <link name="base_link"/>
  <!-- End of link list -->
  <!-- Joint list -->
  <!--bind the rail to word_frame, can be disabled if using modile platform-->
  <joint name="gantry_to_base_link" type="fixed">
    <origin rpy="0 0 0" xyz="1.550 8.675 5.7766"/>
    <parent link="base_link"/>
    <child link="gantry_base_link"/>
  </joint>
  <joint name="robot_to_gantry" type="fixed">
    <origin rpy="0 0 0" xyz="0 0 0"/>
    <parent link="gantry_robot_mount"/>
    <child link="robot_base_link"/>
  </joint>
  <joint name="ee_to_robot" type="fixed">
    <parent link="robot_tool0"/>
    <child link="eef_base_link"/>
    <origin rpy="0 0 0" xyz="0 0 0"/>
  </joint>
  <!-- End of joint list -->
</robot>
