<?xml version="1.0" ?>
<!-- =================================================================================== -->
<!-- |    This document was autogenerated by xacro from irb2400_with_linear_track_workspace.xacro | -->
<!-- |    EDITING THIS FILE BY HAND IS NOT RECOMMENDED                                 | -->
<!-- =================================================================================== -->
<robot name="irb2400_workspace" xmlns:xacro="http://ros.org/wiki/xacro">
  <!-- Conversion were obtained from http://www.e-paint.co.uk/Lab_values.asp
       unless otherwise stated. -->
  <link name="world_frame"/>
  <!-- link list -->
  <link name="base_link">
    <visual>
      <origin rpy="0 0 0" xyz="0 0 0"/>
      <geometry>
        <mesh filename="package://abb_irb2400_support/meshes/irb2400/visual/base_link.dae"/>
      </geometry>
      <material name="">
        <color rgba="0.7372549 0.3490196 0.1607843 1"/>
      </material>
    </visual>
    <collision>
      <geometry>
        <mesh filename="package://abb_irb2400_support/meshes/irb2400/collision/base_link.stl"/>
      </geometry>
      <material name="">
        <color rgba="1 1 0 1"/>
      </material>
    </collision>
  </link>
  <link name="link_1">
    <visual>
      <origin rpy="0 0 0" xyz="0 0 0"/>
      <geometry>
        <mesh filename="package://abb_irb2400_support/meshes/irb2400/visual/link_1.dae"/>
      </geometry>
      <material name="">
        <color rgba="0.7372549 0.3490196 0.1607843 1"/>
      </material>
    </visual>
    <collision>
      <origin rpy="0 0 0" xyz="0 0 0"/>
      <geometry>
        <mesh filename="package://abb_irb2400_support/meshes/irb2400/collision/link_1.stl"/>
      </geometry>
      <material name="">
        <color rgba="1 1 0 1"/>
      </material>
    </collision>
  </link>
  <link name="link_2">
    <visual>
      <origin rpy="0 0 0" xyz="0 0 0"/>
      <geometry>
        <mesh filename="package://abb_irb2400_support/meshes/irb2400/visual/link_2.dae"/>
      </geometry>
      <material name="">
        <color rgba="0.7372549 0.3490196 0.1607843 1"/>
      </material>
    </visual>
    <collision>
      <origin rpy="0 0 0" xyz="0 0 0"/>
      <geometry>
        <mesh filename="package://abb_irb2400_support/meshes/irb2400/collision/link_2_whole.stl"/>
      </geometry>
      <material name="">
        <color rgba="1 1 0 1"/>
      </material>
    </collision>
  </link>
  <link name="link_3">
    <visual>
      <origin rpy="0 0 0" xyz="0 0 0"/>
      <geometry>
        <mesh filename="package://abb_irb2400_support/meshes/irb2400/visual/link_3.dae"/>
      </geometry>
      <material name="">
        <color rgba="0.7372549 0.3490196 0.1607843 1"/>
      </material>
    </visual>
    <collision>
      <origin rpy="0 0 0" xyz="0 0 0"/>
      <geometry>
        <mesh filename="package://abb_irb2400_support/meshes/irb2400/collision/link_3.stl"/>
      </geometry>
      <material name="">
        <color rgba="1 1 0 1"/>
      </material>
    </collision>
  </link>
  <link name="link_4">
    <visual>
      <origin rpy="0 0 0" xyz="0 0 0"/>
      <geometry>
        <mesh filename="package://abb_irb2400_support/meshes/irb2400/visual/link_4.dae"/>
      </geometry>
      <material name="">
        <color rgba="0.7372549 0.3490196 0.1607843 1"/>
      </material>
    </visual>
    <collision>
      <origin rpy="0 0 0" xyz="0 0 0"/>
      <geometry>
        <mesh filename="package://abb_irb2400_support/meshes/irb2400/collision/link_4.stl"/>
      </geometry>
      <material name="">
        <color rgba="1 1 0 1"/>
      </material>
    </collision>
  </link>
  <link name="link_5">
    <visual>
      <origin rpy="0 0 0" xyz="0 0 0"/>
      <geometry>
        <mesh filename="package://abb_irb2400_support/meshes/irb2400/visual/link_5.dae"/>
      </geometry>
      <material name="">
        <color rgba="0.7372549 0.3490196 0.1607843 1"/>
      </material>
    </visual>
    <collision>
      <origin rpy="0 0 0" xyz="0 0 0"/>
      <geometry>
        <mesh filename="package://abb_irb2400_support/meshes/irb2400/collision/link_5.stl"/>
      </geometry>
      <material name="">
        <color rgba="1 1 0 1"/>
      </material>
    </collision>
  </link>
  <link name="link_6">
    <visual>
      <origin rpy="0 0 0" xyz="0 0 0"/>
      <geometry>
        <mesh filename="package://abb_irb2400_support/meshes/irb2400/visual/link_6.dae"/>
      </geometry>
      <material name="">
        <color rgba="0.1882353 0.1960784 0.2039216 1"/>
      </material>
    </visual>
    <collision>
      <origin rpy="0 0 0" xyz="0 0 0"/>
      <geometry>
        <mesh filename="package://abb_irb2400_support/meshes/irb2400/collision/link_6.stl"/>
      </geometry>
      <material name="">
        <color rgba="1 1 0 1"/>
      </material>
    </collision>
  </link>
  <link name="tool0"/>
  <!-- end of link list -->
  <!-- joint list -->
  <joint name="joint_1" type="revolute">
    <origin rpy="0 0 0" xyz="0 0 0"/>
    <parent link="base_link"/>
    <child link="link_1"/>
    <axis xyz="0 0 1"/>
    <limit effort="0" lower="-3.1416" upper="3.1416" velocity="2.618"/>
  </joint>
  <joint name="joint_2" type="revolute">
    <origin rpy="0 0 0" xyz="0.1 0 0.615"/>
    <parent link="link_1"/>
    <child link="link_2"/>
    <axis xyz="0 1 0"/>
    <limit effort="0" lower="-1.7453" upper="1.9199" velocity="2.618"/>
  </joint>
  <joint name="joint_3" type="revolute">
    <origin rpy="0 0 0" xyz="0 0 0.705"/>
    <parent link="link_2"/>
    <child link="link_3"/>
    <axis xyz="0 1 0"/>
    <limit effort="0" lower="-1.0472" upper="1.1345" velocity="2.618"/>
  </joint>
  <joint name="joint_4" type="revolute">
    <origin rpy="0 0 0" xyz="0.258 0 0.135"/>
    <parent link="link_3"/>
    <child link="link_4"/>
    <axis xyz="1 0 0"/>
    <limit effort="0" lower="-3.49" upper="3.49" velocity="6.2832"/>
  </joint>
  <joint name="joint_5" type="revolute">
    <origin rpy="0 0 0" xyz="0.497 0 0"/>
    <parent link="link_4"/>
    <child link="link_5"/>
    <axis xyz="0 1 0"/>
    <limit effort="0" lower="-2.0944" upper="2.0944" velocity="6.2832"/>
  </joint>
  <joint name="joint_6" type="revolute">
    <origin rpy="0 0 0" xyz="0.085 0 0"/>
    <parent link="link_5"/>
    <child link="link_6"/>
    <axis xyz="1 0 0"/>
    <limit effort="0" lower="-6.9813" upper="6.9813" velocity="7.854"/>
  </joint>
  <joint name="joint_6-tool0" type="fixed">
    <parent link="link_6"/>
    <child link="tool0"/>
    <origin rpy="0 1.57079632679 0" xyz="0 0 0"/>
  </joint>
  <!-- end of joint list -->
  <!-- ROS base_link to ABB World Coordinates transform -->
  <link name="base"/>
  <joint name="base_link-base" type="fixed">
    <origin rpy="0 0 0" xyz="0 0 0"/>
    <parent link="base_link"/>
    <child link="base"/>
  </joint>
  <!-- eef_frame is Base Link -->
  <link name="eef_frame"/>
  <link name="hotend_tool">
    <visual>
      <geometry>
        <mesh filename="package://asw_end_effector/meshes/visual/asw_hotend_end_effector.stl" scale=".001 .001 .001"/>
      </geometry>
      <material name="grey">
        <color rgba="0.5 0.5 0.5 1.0"/>
      </material>
    </visual>
    <collision>
      <geometry>
        <mesh filename="package://asw_end_effector/meshes/collision/asw_hotend_end_effector_shrinked_tip-4mm.stl" scale=".001 .001 .001"/>
      </geometry>
      <material name="red">
        <color rgba="1 0 0 1"/>
      </material>
    </collision>
  </link>
  <joint name="eef_frame_to_hotend_tool" type="fixed">
    <parent link="eef_frame"/>
    <child link="hotend_tool"/>
    <origin rpy="0 0 0" xyz="0.000088 0.000769 -0.002121"/>
  </joint>
  <link name="tmp_tcp_frame"/>
  <!--The actual 'useful' work frame-->
  <link name="tcp_frame"/>
  <!--The actual 'useful' work frame-->
  <joint name="eef_to_hotend_tcp_frame" type="fixed">
    <parent link="eef_frame"/>
    <child link="tmp_tcp_frame"/>
    <origin rpy="0 1.57079632679 0" xyz="0.150539 0.001052 0.119157"/>
  </joint>
  <joint name="tmp_to_tcp_frame" type="fixed">
    <parent link="tmp_tcp_frame"/>
    <child link="tcp_frame"/>
    <origin xyz="0 0 0.0"/>
  </joint>
  <link name="demo_cell_base_link"/>
  <material name="workcell_material">
    <color rgba="0.8 1.0 0.8 0.2"/>
  </material>
  <link name="workcell_bounds">
    <!-- visual geometries -->
    <!--<visual> -->
    <!-- top -->
    <!-- <origin xyz="0 0 ${workcell_height}"/>
      <geometry>
        <box size="${workcell_length} ${workcell_width} ${workcell_thickness}"/>
      </geometry>
      <material name="workcell_material"/>
    </visual> -->
    <visual>
      <!-- right ( +x ) -->
      <origin xyz="4.0 0 1.5"/>
      <geometry>
        <box size="0.01 5.0 3.0"/>
      </geometry>
      <material name="workcell_material"/>
    </visual>
    <visual>
      <!-- bottom -->
      <material name="workcell_material"/>
      <origin xyz="0 0 0"/>
      <geometry>
        <box size="8.0 5.0 0.01"/>
      </geometry>
    </visual>
    <visual>
      <!-- left ( -x ) -->
      <origin xyz="-4.0 0 1.5"/>
      <geometry>
        <box size="0.01 5.0 3.0"/>
      </geometry>
      <material name="workcell_material"/>
    </visual>
    <!--<visual>-->
    <!-- front ( +y ) -->
    <!--<origin xyz="0 ${0.5*workcell_width} ${0.5*workcell_height}"/>
      <geometry>
        <box size="${workcell_length} ${workcell_thickness} ${workcell_height}"/>
      </geometry>
      <material name="workcell_material"/>
    </visual>-->
    <visual>
      <!-- rear ( -y ) -->
      <origin xyz="0 -2.5 1.5"/>
      <geometry>
        <box size="8.0 0.01 3.0"/>
      </geometry>
      <material name="workcell_material"/>
    </visual>
    <!-- collision geometries -->
    <collision>
      <!-- top -->
      <origin xyz="0 0 3.0"/>
      <geometry>
        <box size="8.0 5.0 0.01"/>
      </geometry>
      <material name="workcell_material"/>
    </collision>
    <collision>
      <!-- right ( +x ) -->
      <origin xyz="4.0 0 1.5"/>
      <geometry>
        <box size="0.01 5.0 3.0"/>
      </geometry>
      <material name="workcell_material"/>
    </collision>
    <collision>
      <!-- bottom -->
      <material name="workcell_material"/>
      <origin xyz="0 0 0"/>
      <geometry>
        <box size="8.0 5.0 0.01"/>
      </geometry>
    </collision>
    <collision>
      <!-- left ( -x ) -->
      <origin xyz="-4.0 0 1.5"/>
      <geometry>
        <box size="0.01 5.0 3.0"/>
      </geometry>
      <material name="workcell_material"/>
    </collision>
    <collision>
      <!-- front ( +y ) -->
      <origin xyz="0 2.5 1.5"/>
      <geometry>
        <box size="8.0 0.01 3.0"/>
      </geometry>
      <material name="workcell_material"/>
    </collision>
    <collision>
      <!-- rear ( -y ) -->
      <origin xyz="0 -2.5 1.5"/>
      <geometry>
        <box size="8.0 0.01 3.0"/>
      </geometry>
      <material name="workcell_material"/>
    </collision>
  </link>
  <link name="rail">
    <visual>
      <origin xyz="0 0 0"/>
      <geometry>
        <box size="4 0.1 0.1"/>
      </geometry>
      <material name="yellow">
        <color rgba="1.0 1.0 0 1.0"/>
      </material>
    </visual>
    <collision>
      <origin xyz="0 0 0"/>
      <geometry>
        <box size="4 0.1 0.1"/>
      </geometry>
      <material name="yellow">
        <color rgba="1.0 1.0 0 1.0"/>
      </material>
    </collision>
  </link>
  <joint name="cell_base_to_bounds" type="fixed">
    <parent link="demo_cell_base_link"/>
    <child link="workcell_bounds"/>
    <origin xyz="0 0 -0.1"/>
  </joint>
  <joint name="cell_base_to_rail" type="fixed">
    <parent link="demo_cell_base_link"/>
    <child link="rail"/>
    <origin xyz="0 0 0"/>
  </joint>
  <joint name="rail_to_robot_base_link" type="prismatic">
    <parent link="rail"/>
    <child link="base_link"/>
    <origin xyz="0 0 0.05"/>
    <axis xyz="1 0 0"/>
    <limit effort="1" lower="-2" upper="2" velocity="1"/>
  </joint>
  <!-- Attach the end effector to the end of the robot arm (tool0) -->
  <joint name="link_t_to_eef" type="fixed">
    <parent link="tool0"/>
    <child link="eef_frame"/>
    <origin rpy="0 0 0" xyz="0 0 0"/>
  </joint>
  <joint name="world_to_demo_cell" type="fixed">
    <parent link="world_frame"/>
    <child link="demo_cell_base_link"/>
    <origin rpy="0 0 0" xyz="0 0 0"/>
  </joint>
</robot>
