<?xml version="1.0" ?>
<robot name="framefab_irb2400_simple_track" xmlns:xacro="http://ros.org/wiki/xacro">

	<xacro:property name="half_pi" value="1.5707963267948966"/>

	<xacro:include filename="$(find framefab_irb6600_support)/urdf/resources/materials.xacro"/>
  <xacro:include filename="$(find abb_irb2400_support)/urdf/irb2400_macro.xacro"/>

	<xacro:include filename="$(find framefab_irb6600_support)/urdf/simple_linear_track_macro.xacro"/>

	<!--	<xacro:include filename="$(find asw_end_effector)/urdf/asw_eef_macro.xacro"/>-->
	<!--	<xacro:include filename="$(find framefab_irb6600_support)/urdf/simple_linear_track_demo_cell_macro.xacro"/>-->

  <xacro:abb_irb2400 prefix="robot_"/>
<!--  <xacro:asw_eef prefix="eef_"/>-->
  <xacro:simple_linear_track prefix="linear_axis_"/>
	<!--  <xacro:simple_linear_track_demo_cell prefix=""/>-->

	<!-- Link list -->
  <link name="base_link"/>
	<!-- End of link list -->

	<!-- Joint list -->

<!--	<joint name="robot_to_base_link" type="fixed">-->
<!--    <origin xyz="0 0 0" rpy="0 0 ${half_pi}"/>-->
<!--    <parent link="base_link"/>-->
<!--    <child link="robot_base_link"/>-->
<!--  </joint>-->

<!--	bind the rail to word_frame, can be disabled if using modile platform-->
	<joint name="linear_axis_to_base_link" type="fixed">
    <origin xyz="0 0 0" rpy="0 0 0"/>
    <parent link="base_link"/>
    <child link="linear_axis_base_link"/>
  </joint>

<!--  <joint name="robot_to_linear_axis" type="fixed">-->
<!--    <origin xyz="0 0 0" rpy="0 0 -${half_pi}"/>-->
<!--    <parent link="linear_axis_robot_mount"/>-->
<!--    <child link="robot_base_link"/>-->
<!--  </joint>-->

  <joint name="actuation_joint" type="prismatic">
    <parent link="linear_axis_base_link" />
    <child link="robot_base_link" />
    <origin xyz="0 0 0.05"/>
    <axis xyz="1 0 0"/>
    <limit lower="-2" upper="2" effort="1" velocity="0.1"/>
  </joint>

<!--	<joint name="ee_to_robot" type="fixed">-->
<!--		<parent link="robot_tool0"/>-->
<!--		<child link="eef_base_link"/>-->
<!--		<origin xyz="0 0 0" rpy="0 0 0"/>-->
<!--	</joint>-->
	<!-- End of joint list -->

</robot>
