<?xml version="1.0" ?>
<!-- =================================================================================== -->
<!-- |    This document was autogenerated by xacro from choreo_kr150_2_linear_track_workspace.xacro | -->
<!-- |    EDITING THIS FILE BY HAND IS NOT RECOMMENDED                                 | -->
<!-- =================================================================================== -->
<robot name="choreo_kr150_2_workspace" xmlns:xacro="http://ros.org/wiki/xacro">
  <!-- LINKS -->
  <!-- base link -->
  <link name="robot_base_link">
    <visual>
      <origin rpy="0 0 0" xyz="0 0 0"/>
      <geometry>
        <mesh filename="package://kuka_kr150_support/meshes/kr150_2/visual/base_link.dae"/>
      </geometry>
    </visual>
    <collision>
      <origin rpy="0 0 0" xyz="0 0 0"/>
      <geometry>
        <mesh filename="package://kuka_kr150_support/meshes/kr150_2/collision/base_link.stl"/>
      </geometry>
    </collision>
  </link>
  <!-- link 1 (A1) -->
  <link name="robot_link_1">
    <visual>
      <origin rpy="0 0 0" xyz="0 0 0"/>
      <geometry>
        <mesh filename="package://kuka_kr150_support/meshes/kr150_2/visual/link_1.dae"/>
      </geometry>
    </visual>
    <collision>
      <origin rpy="0 0 0" xyz="0 0 0"/>
      <geometry>
        <mesh filename="package://kuka_kr150_support/meshes/kr150_2/collision/link_1.stl"/>
      </geometry>
    </collision>
  </link>
  <!-- link 2 -->
  <link name="robot_link_2">
    <visual>
      <origin rpy="0 0 0" xyz="0 0 0"/>
      <geometry>
        <mesh filename="package://kuka_kr150_support/meshes/kr150_2/visual/link_2.dae"/>
      </geometry>
    </visual>
    <collision>
      <origin rpy="0 0 0" xyz="0 0 0"/>
      <geometry>
        <mesh filename="package://kuka_kr150_support/meshes/kr150_2/collision/link_2.stl"/>
      </geometry>
    </collision>
  </link>
  <!-- link 3 -->
  <link name="robot_link_3">
    <visual>
      <origin rpy="0 0 0" xyz="0 0 0"/>
      <geometry>
        <mesh filename="package://kuka_kr150_support/meshes/kr150_2/visual/link_3.dae"/>
      </geometry>
    </visual>
    <collision>
      <origin rpy="0 0 0" xyz="0 0 0"/>
      <geometry>
        <mesh filename="package://kuka_kr150_support/meshes/kr150_2/collision/link_3.stl"/>
      </geometry>
    </collision>
  </link>
  <!-- link 4 -->
  <link name="robot_link_4">
    <visual>
      <origin rpy="0 0 0" xyz="0 0 0"/>
      <geometry>
        <mesh filename="package://kuka_kr150_support/meshes/kr150_2/visual/link_4.dae"/>
      </geometry>
    </visual>
    <collision>
      <origin rpy="0 0 0" xyz="0 0 0"/>
      <geometry>
        <mesh filename="package://kuka_kr150_support/meshes/kr150_2/collision/link_4.stl"/>
      </geometry>
    </collision>
  </link>
  <!-- link 5 -->
  <link name="robot_link_5">
    <visual>
      <origin rpy="0 0 0" xyz="0 0 0"/>
      <geometry>
        <mesh filename="package://kuka_kr150_support/meshes/kr150_2/visual/link_5.dae"/>
      </geometry>
    </visual>
    <collision>
      <origin rpy="0 0 0" xyz="0 0 0"/>
      <geometry>
        <mesh filename="package://kuka_kr150_support/meshes/kr150_2/collision/link_5.stl"/>
      </geometry>
    </collision>
  </link>
  <!-- link 6 -->
  <link name="robot_link_6">
    <visual>
      <origin rpy="0 0 0" xyz="0 0 0"/>
      <geometry>
        <mesh filename="package://kuka_kr150_support/meshes/kr150_2/visual/link_6.dae"/>
      </geometry>
    </visual>
    <collision>
      <origin rpy="0 0 0" xyz="0 0 0"/>
      <geometry>
        <mesh filename="package://kuka_kr150_support/meshes/kr150_2/collision/link_6.stl"/>
      </geometry>
    </collision>
  </link>
  <!-- tool link -->
  <!-- This frame corresponds to the $FLANGE coordinate system in KUKA KRC controllers. -->
  <link name="robot_tool0"/>
  <!-- END LINKS -->
  <!-- JOINTS -->
  <!-- joint 1 (A1) -->
  <joint name="robot_joint_a1" type="revolute">
    <origin rpy="0 0 0" xyz="0 0 0.75"/>
    <parent link="robot_base_link"/>
    <child link="robot_link_1"/>
    <axis xyz="0 0 -1"/>
    <limit effort="0" lower="-3.22885911619" upper="3.22885911619" velocity="1.91986217719"/>
  </joint>
  <!-- joint 2 (A2) -->
  <joint name="robot_joint_a2" type="revolute">
    <origin rpy="0 0 0" xyz="0.35 0 0"/>
    <parent link="robot_link_1"/>
    <child link="robot_link_2"/>
    <axis xyz="0 1 0"/>
    <limit effort="0" lower="-2.54818070791" upper="0.0" velocity="1.91986217719"/>
  </joint>
  <!-- joint 3 (A3) -->
  <joint name="robot_joint_a3" type="revolute">
    <origin rpy="0 0 0" xyz="1.25 0 0"/>
    <parent link="robot_link_2"/>
    <child link="robot_link_3"/>
    <axis xyz="0 1 0"/>
    <limit effort="0" lower="-2.07694180987" upper="2.70526034059" velocity="1.74532925199"/>
  </joint>
  <!-- joint 4 (A4) -->
  <joint name="robot_joint_a4" type="revolute">
    <origin rpy="0 0 0" xyz="0 0 -0.055"/>
    <parent link="robot_link_3"/>
    <child link="robot_link_4"/>
    <axis xyz="-1 0 0"/>
    <limit effort="0" lower="-6.10865238198" upper="6.10865238198" velocity="2.96705972839"/>
  </joint>
  <!-- joint 5 (A5) -->
  <joint name="robot_joint_a5" type="revolute">
    <origin rpy="0 0 0" xyz="1.1 0 0"/>
    <parent link="robot_link_4"/>
    <child link="robot_link_5"/>
    <axis xyz="0 1 0"/>
    <limit effort="0" lower="-2.18166156499" upper="2.18166156499" velocity="2.96705972839"/>
  </joint>
  <!-- joint 6 (A6) -->
  <joint name="robot_joint_a6" type="revolute">
    <origin rpy="0 0 0" xyz="0.23 0 0"/>
    <parent link="robot_link_5"/>
    <child link="robot_link_6"/>
    <axis xyz="-1 0 0"/>
    <limit effort="0" lower="-6.10865238198" upper="6.10865238198" velocity="4.15388361975"/>
  </joint>
  <!-- tool frame - fixed frame -->
  <joint name="robot_joint_a6-tool0" type="fixed">
    <parent link="robot_link_6"/>
    <child link="robot_tool0"/>
    <origin rpy="0 1.57079632679 0" xyz="0 0 0"/>
  </joint>
  <!-- END JOINTS -->
  <!-- ROS base_link to KUKA $ROBROOT coordinate system transform -->
  <link name="robot_base"/>
  <joint name="robot_base_link-base" type="fixed">
    <origin rpy="0 0 0" xyz="0 0 0"/>
    <parent link="robot_base_link"/>
    <child link="robot_base"/>
  </joint>
  <!-- link list -->
  <link name="eef_base_link">
    <visual>
      <origin rpy="0 0 0" xyz="8.8e-05 0.000769 -0.002121"/>
      <geometry>
        <mesh filename="package://asw_end_effector/meshes/visual/asw_hotend_end_effector.stl" scale=".001 .001 .001"/>
      </geometry>
      <material name="grey">
        <color rgba="0.5 0.5 0.5 1.0"/>
      </material>
    </visual>
    <collision>
      <origin rpy="0 0 0" xyz="8.8e-05 0.000769 -0.002121"/>
      <geometry>
        <mesh filename="package://asw_end_effector/meshes/collision/asw_hotend_end_effector_shrinked_tip-6mm.stl" scale=".001 .001 .001"/>
      </geometry>
      <material name="red">
        <color rgba="1 0 0 1"/>
      </material>
    </collision>
  </link>
  <link name="eef_tcp_frame"/>
  <!-- end of link list -->
  <!-- joint list -->
  <joint name="eef_base_to_tcp" type="fixed">
    <origin rpy="0.0 1.57079632679 0.0" xyz="0.150539 0.001052 0.119157"/>
    <parent link="eef_base_link"/>
    <child link="eef_tcp_frame"/>
  </joint>
  <!-- end of joint list -->
  <!--	Link list-->
  <link name="linear_axis_base_link">
    <visual>
      <geometry>
        <mesh filename="package://ucla_linear_axis/meshes/visual/ucla_linear_axis_visual_rail.stl" scale=".001 .001 .001"/>
      </geometry>
      <material name="">
        <color rgba="0.772549019608 0.780392156863 0.76862745098 1.0"/>
      </material>
    </visual>
    <collision>
      <geometry>
        <mesh filename="package://ucla_linear_axis/meshes/collision/ucla_linear_axis_collision_rail.stl" scale=".001 .001 .001"/>
      </geometry>
      <material name="">
        <color rgba="0.772549019608 0.780392156863 0.76862745098 1.0"/>
      </material>
    </collision>
  </link>
  <link name="linear_axis_zero"/>
  <link name="linear_axis_carriage">
    <visual>
      <geometry>
        <mesh filename="package://ucla_linear_axis/meshes/visual/ucla_linear_axis_visual_carriage.stl" scale=".001 .001 .001"/>
      </geometry>
      <material name="">
        <color rgba="0.15 0.415 0.165 1.0"/>
      </material>
    </visual>
    <collision>
      <geometry>
        <mesh filename="package://ucla_linear_axis/meshes/collision/ucla_linear_axis_collision_carriage.stl" scale=".001 .001 .001"/>
      </geometry>
      <material name="">
        <color rgba="0.15 0.415 0.165 1.0"/>
      </material>
    </collision>
  </link>
  <link name="linear_axis_robot_mount"/>
  <!--	End of link list-->
  <!-- Joint list -->
  <joint name="linear_axis_joint_1" type="fixed">
    <parent link="linear_axis_base_link"/>
    <child link="linear_axis_zero"/>
    <origin rpy="0 0 0" xyz="-3.153 -0.212 0.470"/>
  </joint>
  <joint name="linear_axis_actuation_joint" type="prismatic">
    <parent link="linear_axis_zero"/>
    <child link="linear_axis_carriage"/>
    <origin rpy="0 0 0" xyz="0 0 0"/>
    <axis xyz="1 0 0"/>
    <limit effort="1" lower="0" upper="5.4" velocity="1"/>
  </joint>
  <joint name="linear_axis_joint_3" type="fixed">
    <parent link="linear_axis_carriage"/>
    <child link="linear_axis_robot_mount"/>
    <origin rpy="0 0 0" xyz="0 0 0.470"/>
  </joint>
  <!-- End of joint list -->
  <!-- Link list -->
  <link name="base_link"/>
  <!-- End of link list -->
  <material name="workcell_material">
    <color rgba="0.8 1.0 0.8 0.2"/>
  </material>
  <link name="print_bed">
    <visual>
      <origin xyz="2.1 0 0.395"/>
      <geometry>
        <box size="1.0 3.0 0.01"/>
      </geometry>
      <material name="workcell_material"/>
    </visual>
  </link>
  <joint name="world_to_print_bed" type="fixed">
    <parent link="base_link"/>
    <child link="print_bed"/>
    <origin xyz="0 0 0"/>
  </joint>
  <!-- Joint list -->
  <!--bind the rail to word_frame, can be disabled if using modile platform-->
  <joint name="linear_axis_to_base_link" type="fixed">
    <origin rpy="0 0 1.57079632679" xyz="0 0 0"/>
    <parent link="base_link"/>
    <child link="linear_axis_base_link"/>
  </joint>
  <joint name="robot_to_linear_axis" type="fixed">
    <origin rpy="0 0 -1.57079632679" xyz="0 0 0"/>
    <parent link="linear_axis_robot_mount"/>
    <child link="robot_base_link"/>
  </joint>
  <joint name="ee_to_robot" type="fixed">
    <parent link="robot_tool0"/>
    <child link="eef_base_link"/>
    <origin rpy="0 0 0" xyz="0 0 0"/>
  </joint>
  <!-- End of joint list -->
</robot>
